Workbook
Name ChatCAC: 'Rev Model Assumptions'!$C$8
Name ChatChurn: 'Rev Model Assumptions'!$C$12
Name ChatPrice: 'Rev Model Assumptions'!$C$4
Name EntCAC: 'Rev Model Assumptions'!$C$10
Name EntPrice: 'Rev Model Assumptions'!$C$6
Name ProCAC: 'Rev Model Assumptions'!$C$9
Name ProChurn: 'Rev Model Assumptions'!$C$13
Name ProPrice: 'Rev Model Assumptions'!$C$5
Name Y1ChatMRR: 'Yearly Summary'!$B$18
Name Y1Growth: 'Rev Model Assumptions'!$C$18
Name Y1GrowthPro: 'Rev Model Assumptions'!$C$24
Name Y1ProMRR: 'Yearly Summary'!$B$19
Name Y1Revenue: 'Yearly Summary'!$B$21
Name Y2Growth: 'Rev Model Assumptions'!$C$19
Name Y2GrowthEnterprise: 'Rev Model Assumptions'!$C$30
Name Y2GrowthPro: 'Rev Model Assumptions'!$C$25
Name Y2Revenue: 'Yearly Summary'!$C$21
Name Y3Growth: 'Rev Model Assumptions'!$C$20
Name Y3GrowthEnterprise: 'Rev Model Assumptions'!$C$31
Name Y3GrowthPro: 'Rev Model Assumptions'!$C$26
Name Y3Revenue: 'Yearly Summary'!$D$21
Name Y4Growth: 'Rev Model Assumptions'!$C$21
Name Y4GrowthEnterprise: 'Rev Model Assumptions'!$C$32
Name Y4GrowthPro: 'Rev Model Assumptions'!$C$27
Name Y4Revenue: 'Yearly Summary'!$E$21
Name Y5Growth: 'Rev Model Assumptions'!$C$22
Name Y5GrowthEnterprise: 'Rev Model Assumptions'!$C$33
Name Y5GrowthPro: 'Rev Model Assumptions'!$C$28
Name Y5Revenue: 'Yearly Summary'!$F$21

Sheet Dashboard
A1: HYPESTAKE — 5 YEAR CREATOR EQUITY PLATFORM FINANCIAL MODEL
A3: KEY METRICS — Year 5 (2030) | D3: 5-YEAR SUMMARY
A4: Total Creators on Platform | B4: ='Yearly Summary'!F4 -> 50000 | D4: Total Cumulative Revenue | E4: =SUM('Income Statement'!B10:'Income Statement'!F10) -> 28427328
A5: Total Paying Brands | B5: ='Yearly Summary'!F9 -> 2960 | D5: Creator Growth (Y1→Y5) | E5: ='Yearly Summary'!F4/'Yearly Summary'!B4 -> 100
A6: Total Deals Brokered (Y5) | B6: ='Yearly Summary'!F10 -> 16000 | D6: Brand Growth (Y1→Y5) | E6: ='Yearly Summary'!F9/'Yearly Summary'!B9 -> 25.73913
A7: MRR | B7: ='Yearly Summary'!F19 -> 752129.33
A8: ARR | B8: ='Yearly Summary'!F20 -> 9025552
A9: Revenue Mix | B9: ='Yearly Summary'!F11 -> 5.9121622
A11: UNIT ECONOMICS
A12: Metric | B12: LTV | C12: CAC | D12: LTV:CAC | E12: Payback (mo) | F12: Gross Margin
A13: Brand (Blended Y5) | B13: ='Unit Economics'!F11 -> 21627.553 | C13: ='Unit Economics'!F7 -> 1108.1081 | D13: ='Unit Economics'!F12 -> 19.517548 | E13: ='Unit Economics'!F13 -> 2.7324274 | F13: ='Income Statement'!F16 -> 0.88792011
A14: Creator (Y5) | B14: ='Unit Economics'!F22 -> 1696.3178 | C14: ='Unit Economics'!F18 -> 80 | D14: ='Unit Economics'!F23 -> 21.203973 | E14: N/A | F14: ='Income Statement'!F16 -> 0.88792011
A16: YEAR-OVER-YEAR METRICS
A17: Year | B17: Revenue | C17: Growth % | D17: Brands | E17: Creators | F17: Deals | G17: ARPU
A18: 2026 | B18: ='Income Statement'!B10 -> 392253 | C18: N/A | D18: ='Yearly Summary'!B9 -> 115 | E18: ='Yearly Summary'!B4 -> 500 | F18: ='Yearly Summary'!B10 -> 140 | G18: ='Yearly Summary'!B21 -> 3410.8957
A19: 2027 | B19: ='Income Statement'!C10 -> 1167859 | C19: ='Yearly Summary'!C18 -> 1.9773106 | D19: ='Yearly Summary'!C9 -> 295 | E19: ='Yearly Summary'!C4 -> 2000 | F19: ='Yearly Summary'!C10 -> 630 | G19: ='Yearly Summary'!C21 -> 3958.8441
A20: 2028 | B20: ='Income Statement'!D10 -> 3356388 | C20: ='Yearly Summary'!D18 -> 1.8739668 | D20: ='Yearly Summary'!D9 -> 740 | E20: ='Yearly Summary'!D4 -> 8000 | F20: ='Yearly Summary'!D10 -> 2500 | G20: ='Yearly Summary'!D21 -> 4535.6595
A21: 2029 | B21: ='Income Statement'!E10 -> 7287776 | C21: ='Yearly Summary'!E18 -> 1.1713151 | D21: ='Yearly Summary'!E9 -> 1480 | E21: ='Yearly Summary'!E4 -> 20000 | F21: ='Yearly Summary'!E10 -> 6300 | G21: ='Yearly Summary'!E21 -> 4924.173
A22: 2030 | B22: ='Income Statement'!F10 -> 16223052 | C22: ='Yearly Summary'!F18 -> 1.2260635 | D22: ='Yearly Summary'!F9 -> 2960 | E22: ='Yearly Summary'!F4 -> 50000 | F22: ='Yearly Summary'!F10 -> 16000 | G22: ='Yearly Summary'!F21 -> 5480.7608
A24: SCENARIO SUMMARY
A25: Scenario | B25: Y5 ARR | C25: 5Y Revenue | D25: Implied Valuation (10x)
A26: Conservative | B26: =Scenario_Analysis!B35 -> 3790731.8 | C26: =Scenario_Analysis!B34 -> 9551582.2 | D26: =Scenario_Analysis!B36 -> 37907318
A27: Base Case | B27: =Scenario_Analysis!C35 -> 9025552 | C27: =Scenario_Analysis!C34 -> 28427328 | D27: =Scenario_Analysis!C36 -> 90255520
A28: Optimistic | B28: =Scenario_Analysis!D35 -> 16426505 | C28: =Scenario_Analysis!D34 -> 62085284 | D28: =Scenario_Analysis!D36 -> 1.6426505e+08
A29: Stress Test | B29: =Scenario_Analysis!E35 -> 1353832.8 | C29: =Scenario_Analysis!E34 -> 2558459.5 | D29: =Scenario_Analysis!E36 -> 13538328

Sheet Assumptions
A1: HypeStake - Financial Model Assumptions
A2: Central Control Panel — All sheets reference this one | H2: Input Cell
A3: SECTION 1: GENERAL SETTINGS | H3: Calculated Cell
A4: Company Name | B4: HypeStake | E4: Business Type | F4: SaaS
A5: Model Start Year | B5: 2026 | E5: Forecast Period | F5: 5 years
A6: Currency | B6: USD | E6: Tax Rate | F6: 0.21
A7: NOL Limitation % | B7: 0.8
A9: SECTION 2: REVENUE STREAMS & PRICING
A10: A) TRANSACTION FEES
A11: Deal Type | B11: Avg Deal Size ($) | C11: Platform Take-Rate % | D11: Notes
A12: Pure Equity Deals | B12: 0 | C12: 0 | D12: No cash flows through platform (equity only)
A13: Revenue Share Deals | B13: 2500 | C13: 0.08 | D13: % of quarterly cash payouts processed
A14: Cash Deals | B14: 5000 | C14: 0.1 | D14: Flat fee deal brokering
A15: Hybrid Deals (Cash + Equity) | B15: 3500 | C15: 0.09 | D15: Blended rate on cash portion
A16: Rev Share Tracking Fee | B16: 1200 | C16: 0.05 | D16: Ongoing commission tracking
A18: Blended Avg Take-Rate | C18: =AVERAGE(C12:C16) -> 0.064 | D18: Avg across cash-generating deal types
A20: B) BRAND SUBSCRIPTION FEES
A21: Tier | B21: Monthly Price | C21: Year 1 Policy | D21: Avg Months Active/Yr | E21: Features
A22: Explorer (Free) | B22: 0 | C22: Free always | D22: 12 | E22: Basic brand profile, 3 creator searches/mo
A23: Starter | B23: 149 | C23: WAIVED Year 1 | D23: 10 | E23: Unlimited searches, 5 offers/mo, basic analytics
A24: Professional | B24: 399 | C24: WAIVED Year 1 | D24: 11 | E24: Unlimited offers, AI Brand Tools, campaign builder
A25: Enterprise | B25: 999 | C25: WAIVED Year 1 | D25: 12 | E25: Dedicated support, custom compliance, API access, white-label
A27: Subscription Revenue Activation Year | B27: 2 | C27: (Year 2 = 2027) | E27: Year 1 Waiver Flag | F27: 0 | G27: (0 = brands pay from Day 1; Explorer tier remains free)
A29: C) PREMIUM ADD-ONS
A30: Add-On Module | B30: Monthly Price | C30: Attach Rate | D30: Description
A31: Compliance Module | B31: 99 | C31: 0.15 | D31: Automated SEC, IRS, FTC compliance
A32: Advanced Analytics Pack | B32: 49 | C32: 0.15 | D32: Creator Genome deep insights
A33: Early Liquidity Module | B33: 199 | C33: 0.15 | D33: Secondary market access for creator equity
A34: Avg Add-On Attach Rate | C34: 0.15 | D34: % of paying brands
A36: SECTION 3: USER ACQUISITION — TWO-SIDED
A37: Creator Acquisition
B38: Y1 (2026) | C38: Y2 (2027) | D38: Y3 (2028) | E38: Y4 (2029) | F38: Y5 (2030)
A39: CAC per Creator | B39: 25 | C39: 30 | D39: 40 | E39: 60 | F39: 80
A40: Creators Acquired per Year | B40: 500 | C40: 2000 | D40: 8000 | E40: 20000 | F40: 50000
A41: % Completing at Least 1 Deal | B41: 0.15 | C41: 0.2 | D41: 0.25 | E41: 0.3 | F41: 0.35
A43: Explorer→Paid Conversion % | B43: N/A | C43: 0.12 | D43: 0.15 | E43: 0.18 | F43: 0.2
A44: Creators are FREE (no subscription)
A46: Brand Acquisition
A47: CAC by Tier | B47: CAC ($)
A48: Starter | B48: 800
...

Sheet Income Statement
A1: HypeStake - Income Statement (5-Year Projections)
H3: NOL Limitation %: | I3: =Assumptions!B7 -> 0.8
B4: 2026 | C4: 2027 | D4: 2028 | E4: 2029 | F4: 2030 | H4: Tax Rate: | I4: =Assumptions!F6 -> 0.21
A6: REVENUE
A7: Transaction Fee Revenue | B7: =Assumptions!B66*Assumptions!$B$13*Assumptions!$B$71*Assumptions!$C$13+Assumptions!B67*Assumptions!$B$14*Assumptions!$C$14+Assumptions!B68*Assumptions!$B$15*Assumptions!$C$15+Assumptions!B66*Assumptions!$B$16*Assumptions!$B$71*Assumptions!$C$16 -> 57500 | C7: =Assumptions!C66*Assumptions!$B$13*Assumptions!$B$71*Assumptions!$C$13+Assumptions!C67*Assumptions!$B$14*Assumptions!$C$14+Assumptions!C68*Assumptions!$B$15*Assumptions!$C$15+Assumptions!C66*Assumptions!$B$16*Assumptions!$B$71*Assumptions!$C$16 -> 277500 | D7: =Assumptions!D66*Assumptions!$B$13*Assumptions!$B$71*Assumptions!$C$13+Assumptions!D67*Assumptions!$B$14*Assumptions!$C$14+Assumptions!D68*Assumptions!$B$15*Assumptions!$C$15+Assumptions!D66*Assumptions!$B$16*Assumptions!$B$71*Assumptions!$C$16 -> 1100000 | E7: =Assumptions!E66*Assumptions!$B$13*Assumptions!$B$71*Assumptions!$C$13+Assumptions!E67*Assumptions!$B$14*Assumptions!$C$14+Assumptions!E68*Assumptions!$B$15*Assumptions!$C$15+Assumptions!E66*Assumptions!$B$16*Assumptions!$B$71*Assumptions!$C$16 -> 2775000 | F7: =Assumptions!F66*Assumptions!$B$13*Assumptions!$B$71*Assumptions!$C$13+Assumptions!F67*Assumptions!$B$14*Assumptions!$C$14+Assumptions!F68*Assumptions!$B$15*Assumptions!$C$15+Assumptions!F66*Assumptions!$B$16*Assumptions!$B$71*Assumptions!$C$16 -> 7197500
A8: Brand Subscription Revenue | B8: =IF(Assumptions!$F$27=1,0,Assumptions!B52*Assumptions!$B$23*Assumptions!$D$23+Assumptions!B53*Assumptions!$B$24*Assumptions!$D$24+Assumptions!B54*Assumptions!$B$25*Assumptions!$D$25) -> 310810 | C8: =Assumptions!C52*Assumptions!$B$23*Assumptions!$D$23+Assumptions!C53*Assumptions!$B$24*Assumptions!$D$24+Assumptions!C54*Assumptions!$B$25*Assumptions!$D$25 -> 828940 | D8: =Assumptions!D52*Assumptions!$B$23*Assumptions!$D$23+Assumptions!D53*Assumptions!$B$24*Assumptions!$D$24+Assumptions!D54*Assumptions!$B$25*Assumptions!$D$25 -> 2102320 | E8: =Assumptions!E52*Assumptions!$B$23*Assumptions!$D$23+Assumptions!E53*Assumptions!$B$24*Assumptions!$D$24+Assumptions!E54*Assumptions!$B$25*Assumptions!$D$25 -> 4204640 | F8: =Assumptions!F52*Assumptions!$B$23*Assumptions!$D$23+Assumptions!F53*Assumptions!$B$24*Assumptions!$D$24+Assumptions!F54*Assumptions!$B$25*Assumptions!$D$25 -> 8409280
A9: Premium Add-On Revenue | B9: =(Assumptions!B52+Assumptions!B53+Assumptions!B54)*Assumptions!$C$34*(Assumptions!$B$31+Assumptions!$B$32+Assumptions!$B$33)/3*12 -> 23943 | C9: =(Assumptions!C52+Assumptions!C53+Assumptions!C54)*Assumptions!$C$34*(Assumptions!$B$31+Assumptions!$B$32+Assumptions!$B$33)/3*12 -> 61419 | D9: =(Assumptions!D52+Assumptions!D53+Assumptions!D54)*Assumptions!$C$34*(Assumptions!$B$31+Assumptions!$B$32+Assumptions!$B$33)/3*12 -> 154068 | E9: =(Assumptions!E52+Assumptions!E53+Assumptions!E54)*Assumptions!$C$34*(Assumptions!$B$31+Assumptions!$B$32+Assumptions!$B$33)/3*12 -> 308136 | F9: =(Assumptions!F52+Assumptions!F53+Assumptions!F54)*Assumptions!$C$34*(Assumptions!$B$31+Assumptions!$B$32+Assumptions!$B$33)/3*12 -> 616272
A10: Total Revenue | B10: =SUM(B7:B9) -> 392253 | C10: =SUM(C7:C9) -> 1167859 | D10: =SUM(D7:D9) -> 3356388 | E10: =SUM(E7:E9) -> 7287776 | F10: =SUM(F7:F9) -> 16223052
A11: Revenue Mix % | B11: =IF(B10=0,"N/A",TEXT(B7/B10,"0%")&" | "&TEXT(B8/B10,"0%")&" | "&TEXT(B9/B10,"0%")) -> 15% | 79% | 6% | C11: =IF(C10=0,"N/A",TEXT(C7/C10,"0%")&" | "&TEXT(C8/C10,"0%")&" | "&TEXT(C9/C10,"0%")) -> 24% | 71% | 5% | D11: =IF(D10=0,"N/A",TEXT(D7/D10,"0%")&" | "&TEXT(D8/D10,"0%")&" | "&TEXT(D9/D10,"0%")) -> 33% | 63% | 5% | E11: =IF(E10=0,"N/A",TEXT(E7/E10,"0%")&" | "&TEXT(E8/E10,"0%")&" | "&TEXT(E9/E10,"0%")) -> 38% | 58% | 4% | F11: =IF(F10=0,"N/A",TEXT(F7/F10,"0%")&" | "&TEXT(F8/F10,"0%")&" | "&TEXT(F9/F10,"0%")) -> 44% | 52% | 4%
A13: COST OF GOODS SOLD
A14: Cost of Revenue | B14: ='Cost of Revenue'!B48 -> 42146.617 | C14: ='Cost of Revenue'!C48 -> 122390.32 | D14: ='Cost of Revenue'!D48 -> 356578.79 | E14: ='Cost of Revenue'!E48 -> 784619.99 | F14: ='Cost of Revenue'!F48 -> 1818277.9
A15: Gross Profit | B15: =B10-B14 -> 350106.38 | C15: =C10-C14 -> 1045468.7 | D15: =D10-D14 -> 2999809.2 | E15: =E10-E14 -> 6503156 | F15: =F10-F14 -> 14404774
A16: Gross Margin % | B16: =IF(B10=0,0,B15/B10) -> 0.89255247 | C16: =IF(C10=0,0,C15/C10) -> 0.89520112 | D16: =IF(D10=0,0,D15/D10) -> 0.89376115 | E16: =IF(E10=0,0,E15/E10) -> 0.89233753 | F16: =IF(F10=0,0,F15/F10) -> 0.88792011
A18: OPERATING EXPENSES
A19: Research & Development | B19: ='Operating Expenses'!B15 -> 323147.83 | C19: ='Operating Expenses'!C15 -> 970864.49 | D19: ='Operating Expenses'!D15 -> 2072722.7 | E19: ='Operating Expenses'!E15 -> 3692555.8 | F19: ='Operating Expenses'!F15 -> 6288491.2
A20: Sales & Marketing | B20: ='Operating Expenses'!B24 -> 144570.36 | C20: ='Operating Expenses'!C24 -> 763714.88 | D20: ='Operating Expenses'!D24 -> 1616733.1 | E20: ='Operating Expenses'!E24 -> 2779270.4 | F20: ='Operating Expenses'!F24 -> 4900309.7
A21: General & Administrative | B21: ='Operating Expenses'!B32 -> 201000 | C21: ='Operating Expenses'!C32 -> 343400 | D21: ='Operating Expenses'!D32 -> 623968 | E21: ='Operating Expenses'!E32 -> 1216415.7 | F21: ='Operating Expenses'!F32 -> 1711312.3
A22: Stock-Based Compensation | B22: =Personnel!J47*Assumptions!B100 -> 52750 | C22: =Personnel!K47*Assumptions!C100 -> 145080 | D22: =Personnel!L47*Assumptions!D100 -> 231895.04 | E22: =Personnel!M47*Assumptions!E100 -> 294601.88 | F22: =Personnel!N47*Assumptions!F100 -> 376694.46
A23: Total Operating Expenses | B23: =SUM(B19:B22) -> 721468.19 | C23: =SUM(C19:C22) -> 2223059.4 | D23: =SUM(D19:D22) -> 4545318.8 | E23: =SUM(E19:E22) -> 7982843.8 | F23: =SUM(F19:F22) -> 13276808
A24: OpEx as % of Revenue | B24: =IF(B10=0,0,B23/B10) -> 1.839293 | C24: =IF(C10=0,0,C23/C10) -> 1.903534 | D24: =IF(D10=0,0,D23/D10) -> 1.3542293 | E24: =IF(E10=0,0,E23/E10) -> 1.0953745 | F24: =IF(F10=0,0,F23/F10) -> 0.81839149
A26: PROFITABILITY
A27: EBITDA | B27: =B15-B23 -> -371361.81 | C27: =C15-C23 -> -1177590.7 | D27: =D15-D23 -> -1545509.6 | E27: =E15-E23 -> -1479687.8 | F27: =F15-F23 -> 1127966.4
A28: EBITDA Margin % | B28: =IF(B10=0,0,B27/B10) -> -0.94674051 | C28: =IF(C10=0,0,C27/C10) -> -1.0083329 | D28: =IF(D10=0,0,D27/D10) -> -0.46046811 | E28: =IF(E10=0,0,E27/E10) -> -0.20303695 | F28: =IF(F10=0,0,F27/F10) -> 0.069528622
A29: Depreciation & Amortization | B29: =B10*Assumptions!$B$89/Assumptions!$B$90 -> 2353.518 | C29: =C10*Assumptions!$B$89/Assumptions!$B$90 -> 7007.154 | D29: =D10*Assumptions!$B$89/Assumptions!$B$90 -> 20138.328 | E29: =E10*Assumptions!$B$89/Assumptions!$B$90 -> 43726.656 | F29: =F10*Assumptions!$B$89/Assumptions!$B$90 -> 97338.312
A30: EBIT | B30: =B27-B29 -> -373715.32 | C30: =C27-C29 -> -1184597.8 | D30: =D27-D29 -> -1565648 | E30: =E27-E29 -> -1523414.4 | F30: =F27-F29 -> 1030628.1
A31: Interest Expense | B31: 0 | C31: 0 | D31: 0 | E31: 0 | F31: 0
A32: Earnings Before Tax | B32: =B30-B31 -> -373715.32 | C32: =C30-C31 -> -1184597.8 | D32: =D30-D31 -> -1565648 | E32: =E30-E31 -> -1523414.4 | F32: =F30-F31 -> 1030628.1
A34: NOL Deduction Applied | B34: =B43 -> 0 | C34: =C43 -> 0 | D34: =D43 -> 0 | E34: =E43 -> 0 | F34: =F43 -> 824502.51
A35: Taxable Income | B35: =MAX(0,B32-B34) -> 0 | C35: =MAX(0,C32-C34) -> 0 | D35: =MAX(0,D32-D34) -> 0 | E35: =MAX(0,E32-E34) -> 0 | F35: =MAX(0,F32-F34) -> 206125.63
A36: Income Tax | B36: =B35*$I$4 -> 0 | C36: =C35*$I$4 -> 0 | D36: =D35*$I$4 -> 0 | E36: =E35*$I$4 -> 0 | F36: =F35*$I$4 -> 43286.382
A37: Net Income | B37: =B32-B36 -> -373715.32 | C37: =C32-C36 -> -1184597.8 | D37: =D32-D36 -> -1565648 | E37: =E32-E36 -> -1523414.4 | F37: =F32-F36 -> 987341.75
A38: Net Margin % | B38: =IF(B10=0,0,B37/B10) -> -0.95274051 | C38: =IF(C10=0,0,C37/C10) -> -1.0143329 | D38: =IF(D10=0,0,D37/D10) -> -0.46646811 | E38: =IF(E10=0,0,E37/E10) -> -0.20903695 | F38: =IF(F10=0,0,F37/F10) -> 0.060860419
A40: NOL TRACKING
A41: Beginning NOL Balance | B41: 0 | C41: =B44 -> 373715.32 | D41: =C44 -> 1558313.2 | E41: =D44 -> 3123961.1 | F41: =E44 -> 4647375.6
A42: NOL Generated (when EBT < 0) | B42: =IF(B32<0,ABS(B32),0) -> 373715.32 | C42: =IF(C32<0,ABS(C32),0) -> 1184597.8 | D42: =IF(D32<0,ABS(D32),0) -> 1565648 | E42: =IF(E32<0,ABS(E32),0) -> 1523414.4 | F42: =IF(F32<0,ABS(F32),0) -> 0
A43: NOL Used | B43: =IF(B32>0,MIN(B41,B32*$I$3),0) -> 0 | C43: =IF(C32>0,MIN(C41,C32*$I$3),0) -> 0 | D43: =IF(D32>0,MIN(D41,D32*$I$3),0) -> 0 | E43: =IF(E32>0,MIN(E41,E32*$I$3),0) -> 0 | F43: =IF(F32>0,MIN(F41,F32*$I$3),0) -> 824502.51
A44: Ending NOL Balance | B44: =B41+B42-B43 -> 373715.32 | C44: =C41+C42-C43 -> 1558313.2 | D44: =D41+D42-D43 -> 3123961.1 | E44: =E41+E42-E43 -> 4647375.6 | F44: =F41+F42-F43 -> 3822873.1

Sheet Operating Expenses
A1: HypeStake - Operating Expenses
B3: 2026 | C3: 2027 | D3: 2028 | E3: 2029 | F3: 2030 | G3: Justification
A5: Total Revenue (from Revenue Calc) | B5: ='Income Statement'!B10 -> 392253 | C5: ='Income Statement'!C10 -> 1167859 | D5: ='Income Statement'!D10 -> 3356388 | E5: ='Income Statement'!E10 -> 7287776 | F5: ='Income Statement'!F10 -> 16223052
A7: R&D EXPENSES
A8: Creator Genome Enhancement | B8: =0.03*B$5 -> 11767.59 | C8: =0.03*C$5 -> 35035.77 | D8: =0.03*D$5 -> 100691.64 | E8: =0.03*E$5 -> 218633.28 | F8: =0.03*F$5 -> 486691.56 | G8: 3.0% of revenue — AI model improvement
A9: Deal Architect Improvements | B9: =0.02*B$5 -> 7845.06 | C9: =0.02*C$5 -> 23357.18 | D9: =0.02*D$5 -> 67127.76 | E9: =0.02*E$5 -> 145755.52 | F9: =0.02*F$5 -> 324461.04 | G9: 2.0% of revenue — Deal structuring AI R&D
A10: Smart Vesting Protocol Dev | B10: =0.015*B$5 -> 5883.795 | C10: =0.015*C$5 -> 17517.885 | D10: =0.015*D$5 -> 50345.82 | E10: =0.015*E$5 -> 109316.64 | F10: =0.015*F$5 -> 243345.78 | G10: 1.5% of revenue — Vesting/compliance protocol
A11: Shadow Cap Table & Portfolio | B11: =0.015*B$5 -> 5883.795 | C11: =0.015*C$5 -> 17517.885 | D11: =0.015*D$5 -> 50345.82 | E11: =0.015*E$5 -> 109316.64 | F11: =0.015*F$5 -> 243345.78 | G11: 1.5% of revenue — Cap table tracking features
A12: Platform Scalability & Security | B12: =0.02*B$5 -> 7845.06 | C12: =0.02*C$5 -> 23357.18 | D12: =0.02*D$5 -> 67127.76 | E12: =0.02*E$5 -> 145755.52 | F12: =0.02*F$5 -> 324461.04 | G12: 2.0% of revenue — Infrastructure scaling
A13: Mobile App Development | B13: =0.01*B$5 -> 3922.53 | C13: =0.01*C$5 -> 11678.59 | D13: =0.01*D$5 -> 33563.88 | E13: =0.01*E$5 -> 72877.76 | F13: =0.01*F$5 -> 162230.52 | G13: 1.0% of revenue — iOS/Android app dev
A14: R&D Personnel Costs | B14: =Personnel!J18+Personnel!J23 -> 280000 | C14: =Personnel!K18+Personnel!K23 -> 842400 | D14: =Personnel!L18+Personnel!L23 -> 1703520 | E14: =Personnel!M18+Personnel!M23 -> 2890900.5 | F14: =Personnel!N18+Personnel!N23 -> 4503955.5 | G14: Engineering + Product team salaries
A15: TOTAL R&D | B15: =SUM(B8:B14) -> 323147.83 | C15: =SUM(C8:C14) -> 970864.49 | D15: =SUM(D8:D14) -> 2072722.7 | E15: =SUM(E8:E14) -> 3692555.8 | F15: =SUM(F8:F14) -> 6288491.2
A17: SALES & MARKETING EXPENSES
A18: Brand Customer Acquisition | B18: =0.05*B$5 -> 19612.65 | C18: =0.15*C$5 -> 175178.85 | D18: =0.12*D$5 -> 402766.56 | E18: =0.1*E$5 -> 728777.6 | F18: =0.08*F$5 -> 1297844.2 | G18: 5-8% declining — lean pre-seed, then grows with brand awareness
A19: Creator Acquisition | B19: =0.02*B$5 -> 7845.06 | C19: =0.04*C$5 -> 46714.36 | D19: =0.03*D$5 -> 100691.64 | E19: =0.025*E$5 -> 182194.4 | F19: =0.02*F$5 -> 324461.04 | G19: 2-4% declining — viral/content/referral, low cost
A20: Partnership Development | B20: =0.03*B$5 -> 11767.59 | C20: =0.07*C$5 -> 81750.13 | D20: =0.05*D$5 -> 167819.4 | E20: =0.04*E$5 -> 291511.04 | F20: =0.03*F$5 -> 486691.56 | G20: 3-7% declining — agency/network partnerships
A21: Brand Building & PR | B21: =0.02*B$5 -> 7845.06 | C21: =0.06*C$5 -> 70071.54 | D21: =0.04*D$5 -> 134255.52 | E21: =0.035*E$5 -> 255072.16 | F21: =0.03*F$5 -> 486691.56 | G21: 2-6% declining — PR, events, thought leadership
A22: Sales Personnel | B22: =Personnel!J30 -> 37500 | C22: =Personnel!K30 -> 234000 | D22: =Personnel!L30 -> 578656 | E22: =Personnel!M30 -> 866145.28 | F22: =Personnel!N30 -> 1462323.2
A23: Customer Success Personnel | B23: =Personnel!J36 -> 60000 | C23: =Personnel!K36 -> 156000 | D23: =Personnel!L36 -> 232544 | E23: =Personnel!M36 -> 455569.92 | F23: =Personnel!N36 -> 842298.16
A24: TOTAL S&M | B24: =SUM(B18:B23) -> 144570.36 | C24: =SUM(C18:C23) -> 763714.88 | D24: =SUM(D18:D23) -> 1616733.1 | E24: =SUM(E18:E23) -> 2779270.4 | F24: =SUM(F18:F23) -> 4900309.7
A26: GENERAL & ADMINISTRATIVE
A27: Rent & Utilities | B27: 0 | C27: 0 | D27: 0 | E27: 120000 | F27: 360000 | G27: Remote-first Y1-Y3; office from Y4 (post-Series A)
A28: Legal & Compliance (external) | B28: 35000 | C28: 80000 | D28: 150000 | E28: 250000 | F28: 400000
A29: Insurance (D&O, E&O, Cyber) | B29: 5000 | C29: 18000 | D29: 40000 | E29: 65000 | F29: 100000
A30: Software & Tools ($2K/employee) | B30: =Personnel!B46*2000 -> 11000 | C30: =Personnel!C46*2000 -> 27000 | D30: =Personnel!D46*2000 -> 50000 | E30: =Personnel!E46*2000 -> 84000 | F30: =Personnel!F46*2000 -> 126000
A31: Executive & G&A Personnel | B31: =Personnel!J9+Personnel!J43 -> 150000 | C31: =Personnel!K9+Personnel!K43 -> 218400 | D31: =Personnel!L9+Personnel!L43 -> 383968 | E31: =Personnel!M9+Personnel!M43 -> 697415.68 | F31: =Personnel!N9+Personnel!N43 -> 725312.31
A32: TOTAL G&A | B32: =SUM(B27:B31) -> 201000 | C32: =SUM(C27:C31) -> 343400 | D32: =SUM(D27:D31) -> 623968 | E32: =SUM(E27:E31) -> 1216415.7 | F32: =SUM(F27:F31) -> 1711312.3
A34: TOTAL OPERATING EXPENSES | B34: =B15+B24+B32 -> 668718.19 | C34: =C15+C24+C32 -> 2077979.4 | D34: =D15+D24+D32 -> 4313423.8 | E34: =E15+E24+E32 -> 7688241.9 | F34: =F15+F24+F32 -> 12900113
A35: OpEx as % of Revenue | B35: =B34/B$5 -> 1.7048134 | C35: =C34/C$5 -> 1.7793067 | D35: =D34/D$5 -> 1.2851386 | E35: =E34/E$5 -> 1.0549504 | F35: =F34/F$5 -> 0.79517178

Sheet Balance Sheet
A1: HypeStake - Balance Sheet
A2: All amounts in USD | H2: Days in Year | I2: 365
H3: Prepaid % of OpEx | I3: =Assumptions!B87 -> 0.05
B4: 2026 | C4: 2027 | D4: 2028 | E4: 2029 | F4: 2030 | H4: Accrued % of OpEx | I4: =Assumptions!B88 -> 0.08
H5: Receivables Days | I5: =Assumptions!B84 -> 45
A6: ASSETS | H6: Payables Days | I6: =Assumptions!B85 -> 30
A7: Current Assets | H7: Deferred Revenue Months | I7: =Assumptions!B86 -> 3
A8: Cash & Cash Equivalents | B8: ='Cash Flow Statement'!B48 -> 212432.05 | C8: ='Cash Flow Statement'!C48 -> 2242807.5 | D8: ='Cash Flow Statement'!D48 -> 1157731.1 | E8: ='Cash Flow Statement'!E48 -> 15388474 | F8: ='Cash Flow Statement'!F48 -> 17747144 | H8: CapEx % of Revenue | I8: =Assumptions!B89 -> 0.03
A9: Accounts Receivable | B9: ='Income Statement'!B10*$I$5/$I$2 -> 48359.959 | C9: ='Income Statement'!C10*$I$5/$I$2 -> 143982.62 | D9: ='Income Statement'!D10*$I$5/$I$2 -> 413801.26 | E9: ='Income Statement'!E10*$I$5/$I$2 -> 898492.93 | F9: ='Income Statement'!F10*$I$5/$I$2 -> 2000102.3 | H9: Intangible Amort Years | I9: =Assumptions!B90 -> 5
A10: Prepaid Expenses | B10: ='Income Statement'!B23*$I$3 -> 36073.41 | C10: ='Income Statement'!C23*$I$3 -> 111152.97 | D10: ='Income Statement'!D23*$I$3 -> 227265.94 | E10: ='Income Statement'!E23*$I$3 -> 399142.19 | F10: ='Income Statement'!F23*$I$3 -> 663840.38
A11: Total Current Assets | B11: =SUM(B8:B10) -> 296865.41 | C11: =SUM(C8:C10) -> 2497943.1 | D11: =SUM(D8:D10) -> 1798798.3 | E11: =SUM(E8:E10) -> 16686110 | F11: =SUM(F8:F10) -> 20411087
A13: Non-Current Assets
A14: PP&E (Cumulative CapEx) | B14: ='Income Statement'!B10*$I$8 -> 11767.59 | C14: =B14+'Income Statement'!C10*$I$8 -> 46803.36 | D14: =C14+'Income Statement'!D10*$I$8 -> 147495 | E14: =D14+'Income Statement'!E10*$I$8 -> 366128.28 | F14: =E14+'Income Statement'!F10*$I$8 -> 852819.84
A15: Accumulated Depreciation | B15: ='Income Statement'!B29 -> 2353.518 | C15: =B15+'Income Statement'!C29 -> 9360.672 | D15: =C15+'Income Statement'!D29 -> 29499 | E15: =D15+'Income Statement'!E29 -> 73225.656 | F15: =E15+'Income Statement'!F29 -> 170563.97
A16: Net PP&E | B16: =B14-B15 -> 9414.072 | C16: =C14-C15 -> 37442.688 | D16: =D14-D15 -> 117996 | E16: =E14-E15 -> 292902.62 | F16: =F14-F15 -> 682255.87
A17: Intangible Assets (Creator Genome IP) | B17: =Assumptions!B99 -> 40000 | C17: =B17+Assumptions!C99 -> 115000 | D17: =C17+Assumptions!D99 -> 190000 | E17: =D17+Assumptions!E99 -> 240000 | F17: =E17+Assumptions!F99 -> 290000
A18: Accumulated Intangible Amortization | B18: =B17/$I$9 -> 8000 | C18: =B18+C17/$I$9 -> 31000 | D18: =C18+D17/$I$9 -> 69000 | E18: =D18+E17/$I$9 -> 117000 | F18: =E18+F17/$I$9 -> 175000
A19: Net Intangible Assets | B19: =B17-B18 -> 32000 | C19: =C17-C18 -> 84000 | D19: =D17-D18 -> 121000 | E19: =E17-E18 -> 123000 | F19: =F17-F18 -> 115000
A20: Total Non-Current Assets | B20: =B16+B19 -> 41414.072 | C20: =C16+C19 -> 121442.69 | D20: =D16+D19 -> 238996 | E20: =E16+E19 -> 415902.62 | F20: =F16+F19 -> 797255.87
A22: TOTAL ASSETS | B22: =B11+B20 -> 338279.49 | C22: =C11+C20 -> 2619385.8 | D22: =D11+D20 -> 2037794.3 | E22: =E11+E20 -> 17102012 | F22: =F11+F20 -> 21208343
A24: LIABILITIES
A25: Current Liabilities
A26: Accounts Payable | B26: ='Income Statement'!B14*$I$6/$I$2 -> 3464.1055 | C26: ='Income Statement'!C14*$I$6/$I$2 -> 10059.478 | D26: ='Income Statement'!D14*$I$6/$I$2 -> 29307.846 | E26: ='Income Statement'!E14*$I$6/$I$2 -> 64489.314 | F26: ='Income Statement'!F14*$I$6/$I$2 -> 149447.5
A27: Accrued Expenses | B27: ='Income Statement'!B23*$I$4 -> 57717.455 | C27: ='Income Statement'!C23*$I$4 -> 177844.75 | D27: ='Income Statement'!D23*$I$4 -> 363625.51 | E27: ='Income Statement'!E23*$I$4 -> 638627.5 | F27: ='Income Statement'!F23*$I$4 -> 1062144.6
A28: Deferred Revenue | B28: ='Income Statement'!B10*$I$7/12 -> 98063.25 | C28: ='Income Statement'!C10*$I$7/12 -> 291964.75 | D28: ='Income Statement'!D10*$I$7/12 -> 839097 | E28: ='Income Statement'!E10*$I$7/12 -> 1821944 | F28: ='Income Statement'!F10*$I$7/12 -> 4055763
A29: Total Current Liabilities | B29: =SUM(B26:B28) -> 159244.81 | C29: =SUM(C26:C28) -> 479868.98 | D29: =SUM(D26:D28) -> 1232030.4 | E29: =SUM(E26:E28) -> 2525060.8 | F29: =SUM(F26:F28) -> 5267355.1
A31: Long-term Debt | B31: 0 | C31: 0 | D31: 0 | E31: 0 | F31: 0
A32: Total Long-term Liabilities | B32: =B31 -> 0 | C32: =C31 -> 0 | D32: =D31 -> 0 | E32: =E31 -> 0 | F32: =F31 -> 0
A34: TOTAL LIABILITIES | B34: =B29+B32 -> 159244.81 | C34: =C29+C32 -> 479868.98 | D34: =D29+D32 -> 1232030.4 | E34: =E29+E32 -> 2525060.8 | F34: =F29+F32 -> 5267355.1
A36: SHAREHOLDERS' EQUITY
A37: Paid-in Capital (Cumulative Equity Raised) | B37: =Assumptions!B103+'Income Statement'!B22 -> 552750 | C37: =B37+Assumptions!B104+'Income Statement'!C22 -> 3697830 | D37: =C37+'Income Statement'!D22 -> 3929725 | E37: =D37+Assumptions!B105+'Income Statement'!E22 -> 19224327 | F37: =E37+'Income Statement'!F22 -> 19601021
A38: Retained Earnings | B38: ='Income Statement'!B37 -> -373715.32 | C38: =B38+'Income Statement'!C37 -> -1558313.2 | D38: =C38+'Income Statement'!D37 -> -3123961.1 | E38: =D38+'Income Statement'!E37 -> -4647375.6 | F38: =E38+'Income Statement'!F37 -> -3660033.8
A39: Total Equity | B39: =B37+B38 -> 179034.68 | C39: =C37+C38 -> 2139516.8 | D39: =D37+D38 -> 805763.91 | E39: =E37+E38 -> 14576951 | F39: =F37+F38 -> 15940988
A41: TOTAL LIABILITIES + EQUITY | B41: =B34+B39 -> 338279.49 | C41: =C34+C39 -> 2619385.8 | D41: =D34+D39 -> 2037794.3 | E41: =E34+E39 -> 17102012 | F41: =F34+F39 -> 21208343
A43: Balance Check (Assets - L&E) | B43: =B22-B41 -> 0 | C43: =C22-C41 -> 0 | D43: =D22-D41 -> 0 | E43: =E22-E41 -> 0 | F43: =F22-F41 -> 0

Sheet Cash Flow Statement
A1: HypeStake - Cash Flow Statement
A2: All amounts in USD
B5: 2026 | C5: 2027 | D5: 2028 | E5: 2029 | F5: 2030
A7: OPERATING ACTIVITIES
A9: Net Income | B9: ='Income Statement'!B37 -> -373715.32 | C9: ='Income Statement'!C37 -> -1184597.8 | D9: ='Income Statement'!D37 -> -1565648 | E9: ='Income Statement'!E37 -> -1523414.4 | F9: ='Income Statement'!F37 -> 987341.75
A11: Adjustments:
A12: Depreciation & Amortization | B12: ='Income Statement'!B29+'Balance Sheet'!B18 -> 10353.518 | C12: ='Income Statement'!C29+('Balance Sheet'!C18-'Balance Sheet'!B18) -> 30007.154 | D12: ='Income Statement'!D29+('Balance Sheet'!D18-'Balance Sheet'!C18) -> 58138.328 | E12: ='Income Statement'!E29+('Balance Sheet'!E18-'Balance Sheet'!D18) -> 91726.656 | F12: ='Income Statement'!F29+('Balance Sheet'!F18-'Balance Sheet'!E18) -> 155338.31
A13: Stock-Based Compensation | B13: =Personnel!J47*Assumptions!B100 -> 52750 | C13: =Personnel!K47*Assumptions!C100 -> 145080 | D13: =Personnel!L47*Assumptions!D100 -> 231895.04 | E13: =Personnel!M47*Assumptions!E100 -> 294601.88 | F13: =Personnel!N47*Assumptions!F100 -> 376694.46
A15: Changes in Working Capital:
A16: (Increase)/Decrease in AR | B16: =-'Balance Sheet'!B9 -> -48359.959 | C16: =-('Balance Sheet'!C9-'Balance Sheet'!B9) -> -95622.658 | D16: =-('Balance Sheet'!D9-'Balance Sheet'!C9) -> -269818.64 | E16: =-('Balance Sheet'!E9-'Balance Sheet'!D9) -> -484691.67 | F16: =-('Balance Sheet'!F9-'Balance Sheet'!E9) -> -1101609.4
A17: (Increase)/Decrease in Prepaid | B17: =-'Balance Sheet'!B10 -> -36073.41 | C17: =-('Balance Sheet'!C10-'Balance Sheet'!B10) -> -75079.559 | D17: =-('Balance Sheet'!D10-'Balance Sheet'!C10) -> -116112.97 | E17: =-('Balance Sheet'!E10-'Balance Sheet'!D10) -> -171876.25 | F17: =-('Balance Sheet'!F10-'Balance Sheet'!E10) -> -264698.19
A18: Increase/(Decrease) in AP | B18: ='Balance Sheet'!B26 -> 3464.1055 | C18: ='Balance Sheet'!C26-'Balance Sheet'!B26 -> 6595.3729 | D18: ='Balance Sheet'!D26-'Balance Sheet'!C26 -> 19248.367 | E18: ='Balance Sheet'!E26-'Balance Sheet'!D26 -> 35181.468 | F18: ='Balance Sheet'!F26-'Balance Sheet'!E26 -> 84958.187
A19: Increase/(Decrease) in Accrued | B19: ='Balance Sheet'!B27 -> 57717.455 | C19: ='Balance Sheet'!C27-'Balance Sheet'!B27 -> 120127.29 | D19: ='Balance Sheet'!D27-'Balance Sheet'!C27 -> 185780.76 | E19: ='Balance Sheet'!E27-'Balance Sheet'!D27 -> 275002 | F19: ='Balance Sheet'!F27-'Balance Sheet'!E27 -> 423517.11
A20: Increase/(Decrease) in Deferred Rev | B20: ='Balance Sheet'!B28 -> 98063.25 | C20: ='Balance Sheet'!C28-'Balance Sheet'!B28 -> 193901.5 | D20: ='Balance Sheet'!D28-'Balance Sheet'!C28 -> 547132.25 | E20: ='Balance Sheet'!E28-'Balance Sheet'!D28 -> 982847 | F20: ='Balance Sheet'!F28-'Balance Sheet'!E28 -> 2233819
A22: Net Cash from Operations | B22: =B9+B12+B13+SUM(B16:B20) -> -235800.36 | C22: =C9+C12+C13+SUM(C16:C20) -> -859588.74 | D22: =D9+D12+D13+SUM(D16:D20) -> -909384.83 | E22: =E9+E12+E13+SUM(E16:E20) -> -500623.36 | F22: =F9+F12+F13+SUM(F16:F20) -> 2895361.3
A24: INVESTING ACTIVITIES
A26: Capital Expenditures (CapEx) | B26: =-'Income Statement'!B10*Assumptions!$B$89 -> -11767.59 | C26: =-'Income Statement'!C10*Assumptions!$B$89 -> -35035.77 | D26: =-'Income Statement'!D10*Assumptions!$B$89 -> -100691.64 | E26: =-'Income Statement'!E10*Assumptions!$B$89 -> -218633.28 | F26: =-'Income Statement'!F10*Assumptions!$B$89 -> -486691.56
A27: Intangible Asset Investment | B27: =-Assumptions!B99 -> -40000 | C27: =-Assumptions!C99 -> -75000 | D27: =-Assumptions!D99 -> -75000 | E27: =-Assumptions!E99 -> -50000 | F27: =-Assumptions!F99 -> -50000
A29: Net Cash from Investing | B29: =B26+B27 -> -51767.59 | C29: =C26+C27 -> -110035.77 | D29: =D26+D27 -> -175691.64 | E29: =E26+E27 -> -268633.28 | F29: =F26+F27 -> -536691.56
A31: FINANCING ACTIVITIES
A33: Equity Raised | B33: =Assumptions!B103 -> 500000 | C33: =Assumptions!B104 -> 3000000 | D33: 0 | E33: =Assumptions!B105 -> 15000000 | F33: 0
A34: Debt Proceeds / Repayments | B34: 0 | C34: 0 | D34: 0 | E34: 0 | F34: 0
A36: Net Cash from Financing | B36: =B33+B34 -> 500000 | C36: =C33+C34 -> 3000000 | D36: =D33+D34 -> 0 | E36: =E33+E34 -> 15000000 | F36: =F33+F34 -> 0
A38: CASH SUMMARY
A40: Total Cash Flow | B40: =B22+B29+B36 -> 212432.05 | C40: =C22+C29+C36 -> 2030375.5 | D40: =D22+D29+D36 -> -1085076.5 | E40: =E22+E29+E36 -> 14230743 | F40: =F22+F29+F36 -> 2358669.7
A46: Beginning Cash | B46: 0 | C46: =B48 -> 212432.05 | D46: =C48 -> 2242807.5 | E46: =D48 -> 1157731.1 | F46: =E48 -> 15388474
A48: Ending Cash | B48: =B46+B40 -> 212432.05 | C48: =C46+C40 -> 2242807.5 | D48: =D46+D40 -> 1157731.1 | E48: =E46+E40 -> 15388474 | F48: =F46+F40 -> 17747144
A50: Validation: Ending Cash = BS Cash
A52: CASH RUNWAY ANALYSIS
A54: Monthly Net Burn (Ops + Inv) | B54: =(B22+B29)/12 -> -23963.996 | C54: =(C22+C29)/12 -> -80802.043 | D54: =(D22+D29)/12 -> -90423.039 | E54: =(E22+E29)/12 -> -64104.72 | F54: =(F22+F29)/12 -> 196555.81
A55: Months of Runway (End Cash / |Burn|) | B55: =IF(B54<0, B48/ABS(B54), "∞") -> 8.8646336 | C55: =IF(C54<0, C48/ABS(C54), "∞") -> 27.756817 | D55: =IF(D54<0, D48/ABS(D54), "∞") -> 12.803496 | E55: =IF(E54<0, E48/ABS(E54), "∞") -> 240.05213 | F55: =IF(F54<0, F48/ABS(F54), "∞") -> ∞
A56: Cash Positive? | B56: =IF(B54>=0,"✅ YES",IF(B55>=18,"✅ OK",IF(B55>=12,"⚠️ TIGHT","❌ DANGER"))) -> ❌ DANGER | C56: =IF(C54>=0,"✅ YES",IF(C55>=18,"✅ OK",IF(C55>=12,"⚠️ TIGHT","❌ DANGER"))) -> ✅ OK | D56: =IF(D54>=0,"✅ YES",IF(D55>=18,"✅ OK",IF(D55>=12,"⚠️ TIGHT","❌ DANGER"))) -> ⚠️ TIGHT | E56: =IF(E54>=0,"✅ YES",IF(E55>=18,"✅ OK",IF(E55>=12,"⚠️ TIGHT","❌ DANGER"))) -> ✅ OK | F56: =IF(F54>=0,"✅ YES",IF(F55>=18,"✅ OK",IF(F55>=12,"⚠️ TIGHT","❌ DANGER"))) -> ✅ YES
A58: STRESS TEST: Series A Delays 6 Months
A60: Cash if Series A Delayed 6mo | B60: N/A | C60: N/A | D60: N/A | E60: =D48+E54*6 -> 773102.74 | F60: N/A
A61: Months Until Cash-Out (if delayed) | B61: N/A | C61: N/A | D61: N/A | E61: =IF(E54<0, D48/ABS(E54), "∞") -> 18.059997 | F61: N/A
A62: Survival? | E62: =IF(E61>=6, "✅ SURVIVES", "❌ CASH-OUT") -> ✅ SURVIVES

Sheet Personnel
A1: HypeStake - Personnel Plan
A3: Role | B3: 2026 | C3: 2027 | D3: 2028 | E3: 2029 | F3: 2030 | H3: Salary | J3: 2026 | K3: 2027 | L3: 2028 | M3: 2029 | N3: 2030
B4: HC | C4: HC | D4: HC | E4: HC | F4: HC | H4: Annual | J4: $ Total | K4: $ Total | L4: $ Total | M4: $ Total | N4: $ Total
A5: 1. EXECUTIVE TEAM
A6: CEO/Founder (Andrew Rodriguez) | B6: 1 | C6: 1 | D6: 1 | E6: 1 | F6: 1 | H6: 50000 | J6: =B6*$H$6 -> 50000 | K6: =C6*$H$6*(1+Assumptions!$B$98)^1 -> 52000 | L6: =D6*$H$6*(1+Assumptions!$B$98)^2 -> 54080 | M6: =E6*$H$6*(1+Assumptions!$B$98)^3 -> 56243.2 | N6: =F6*$H$6*(1+Assumptions!$B$98)^4 -> 58492.928
A7: CTO | B7: 1 | C7: 1 | D7: 1 | E7: 1 | F7: 1 | H7: 100000 | J7: =B7*$H$7 -> 100000 | K7: =C7*$H$7*(1+Assumptions!$B$98)^1 -> 104000 | L7: =D7*$H$7*(1+Assumptions!$B$98)^2 -> 108160 | M7: =E7*$H$7*(1+Assumptions!$B$98)^3 -> 112486.4 | N7: =F7*$H$7*(1+Assumptions!$B$98)^4 -> 116985.86
A8: CCO (Compliance) | B8: 0 | C8: 0 | D8: 0 | E8: 1 | F8: 1 | H8: 130000 | J8: =B8*$H$8 -> 0 | K8: =C8*$H$8*(1+Assumptions!$B$98)^1 -> 0 | L8: =D8*$H$8*(1+Assumptions!$B$98)^2 -> 0 | M8: =E8*$H$8*(1+Assumptions!$B$98)^3 -> 146232.32 | N8: =F8*$H$8*(1+Assumptions!$B$98)^4 -> 152081.61
A9: Total EXECUTIVE TEAM | B9: =SUM(B6:B8) -> 2 | C9: =SUM(C6:C8) -> 2 | D9: =SUM(D6:D8) -> 2 | E9: =SUM(E6:E8) -> 3 | F9: =SUM(F6:F8) -> 3 | J9: =SUM(J6:J8) -> 150000 | K9: =SUM(K6:K8) -> 156000 | L9: =SUM(L6:L8) -> 162240 | M9: =SUM(M6:M8) -> 314961.92 | N9: =SUM(N6:N8) -> 327560.4
A11: 2. ENGINEERING & AI/ML
A12: Full-Stack Engineer | B12: 1 | C12: 2 | D12: 4 | E12: 6 | F12: 9 | H12: 135000 | J12: =B12*$H$12 -> 135000 | K12: =C12*$H$12*(1+Assumptions!$B$98)^1 -> 280800 | L12: =D12*$H$12*(1+Assumptions!$B$98)^2 -> 584064 | M12: =E12*$H$12*(1+Assumptions!$B$98)^3 -> 911139.84 | N12: =F12*$H$12*(1+Assumptions!$B$98)^4 -> 1421378.2
A13: Head of AI/ML | B13: 0 | C13: 1 | D13: 1 | E13: 1 | F13: 1 | H13: 165000 | J13: =B13*$H$13 -> 0 | K13: =C13*$H$13*(1+Assumptions!$B$98)^1 -> 171600 | L13: =D13*$H$13*(1+Assumptions!$B$98)^2 -> 178464 | M13: =E13*$H$13*(1+Assumptions!$B$98)^3 -> 185602.56 | N13: =F13*$H$13*(1+Assumptions!$B$98)^4 -> 193026.66
A14: ML Engineer | B14: 1 | C14: 1 | D14: 2 | E14: 3 | F14: 5 | H14: 145000 | J14: =B14*$H$14 -> 145000 | K14: =C14*$H$14*(1+Assumptions!$B$98)^1 -> 150800 | L14: =D14*$H$14*(1+Assumptions!$B$98)^2 -> 313664 | M14: =E14*$H$14*(1+Assumptions!$B$98)^3 -> 489315.84 | N14: =F14*$H$14*(1+Assumptions!$B$98)^4 -> 848147.46
A15: Data Scientist | B15: 0 | C15: 0 | D15: 1 | E15: 2 | F15: 4 | H15: 130000 | J15: =B15*$H$15 -> 0 | K15: =C15*$H$15*(1+Assumptions!$B$98)^1 -> 0 | L15: =D15*$H$15*(1+Assumptions!$B$98)^2 -> 140608 | M15: =E15*$H$15*(1+Assumptions!$B$98)^3 -> 292464.64 | N15: =F15*$H$15*(1+Assumptions!$B$98)^4 -> 608326.45
A16: DevOps/Infrastructure | B16: 0 | C16: 0 | D16: 1 | E16: 2 | F16: 3 | H16: 125000 | J16: =B16*$H$16 -> 0 | K16: =C16*$H$16*(1+Assumptions!$B$98)^1 -> 0 | L16: =D16*$H$16*(1+Assumptions!$B$98)^2 -> 135200 | M16: =E16*$H$16*(1+Assumptions!$B$98)^3 -> 281216 | N16: =F16*$H$16*(1+Assumptions!$B$98)^4 -> 438696.96
A17: QA Engineer | B17: 0 | C17: 0 | D17: 1 | E17: 2 | F17: 3 | H17: 95000 | J17: =B17*$H$17 -> 0 | K17: =C17*$H$17*(1+Assumptions!$B$98)^1 -> 0 | L17: =D17*$H$17*(1+Assumptions!$B$98)^2 -> 102752 | M17: =E17*$H$17*(1+Assumptions!$B$98)^3 -> 213724.16 | N17: =F17*$H$17*(1+Assumptions!$B$98)^4 -> 333409.69
A18: Total ENGINEERING & AI/ML | B18: =SUM(B12:B17) -> 2 | C18: =SUM(C12:C17) -> 4 | D18: =SUM(D12:D17) -> 10 | E18: =SUM(E12:E17) -> 16 | F18: =SUM(F12:F17) -> 25 | J18: =SUM(J12:J17) -> 280000 | K18: =SUM(K12:K17) -> 603200 | L18: =SUM(L12:L17) -> 1454752 | M18: =SUM(M12:M17) -> 2373463 | N18: =SUM(N12:N17) -> 3842985.4
A20: 3. PRODUCT & DESIGN
A21: Product Manager | B21: 0 | C21: 1 | D21: 1 | E21: 2 | F21: 2 | H21: 125000 | J21: =B21*$H$21 -> 0 | K21: =C21*$H$21*(1+Assumptions!$B$98)^1 -> 130000 | L21: =D21*$H$21*(1+Assumptions!$B$98)^2 -> 135200 | M21: =E21*$H$21*(1+Assumptions!$B$98)^3 -> 281216 | N21: =F21*$H$21*(1+Assumptions!$B$98)^4 -> 292464.64
A22: UX/UI Designer | B22: 0 | C22: 1 | D22: 1 | E22: 2 | F22: 3 | H22: 105000 | J22: =B22*$H$22 -> 0 | K22: =C22*$H$22*(1+Assumptions!$B$98)^1 -> 109200 | L22: =D22*$H$22*(1+Assumptions!$B$98)^2 -> 113568 | M22: =E22*$H$22*(1+Assumptions!$B$98)^3 -> 236221.44 | N22: =F22*$H$22*(1+Assumptions!$B$98)^4 -> 368505.45
A23: Total PRODUCT & DESIGN | B23: =SUM(B21:B22) -> 0 | C23: =SUM(C21:C22) -> 2 | D23: =SUM(D21:D22) -> 2 | E23: =SUM(E21:E22) -> 4 | F23: =SUM(F21:F22) -> 5 | J23: =SUM(J21:J22) -> 0 | K23: =SUM(K21:K22) -> 239200 | L23: =SUM(L21:L22) -> 248768 | M23: =SUM(M21:M22) -> 517437.44 | N23: =SUM(N21:N22) -> 660970.09
A25: 4. SALES & MARKETING
A26: VP of Sales & Marketing | B26: 0 | C26: 0 | D26: 1 | E26: 1 | F26: 1 | H26: 150000 | J26: =B26*$H$26 -> 0 | K26: =C26*$H$26*(1+Assumptions!$B$98)^1 -> 0 | L26: =D26*$H$26*(1+Assumptions!$B$98)^2 -> 162240 | M26: =E26*$H$26*(1+Assumptions!$B$98)^3 -> 168729.6 | N26: =F26*$H$26*(1+Assumptions!$B$98)^4 -> 175478.78
A27: Brand Account Executive | B27: 0 | C27: 1 | D27: 2 | E27: 4 | F27: 8 | H27: 85000 | J27: =B27*$H$27 -> 0 | K27: =C27*$H$27*(1+Assumptions!$B$98)^1 -> 88400 | L27: =D27*$H$27*(1+Assumptions!$B$98)^2 -> 183872 | M27: =E27*$H$27*(1+Assumptions!$B$98)^3 -> 382453.76 | N27: =F27*$H$27*(1+Assumptions!$B$98)^4 -> 795503.82
A28: Digital Marketer | B28: 0.5 | C28: 1 | D28: 2 | E28: 2 | F28: 3 | H28: 75000 | J28: =B28*$H$28 -> 37500 | K28: =C28*$H$28*(1+Assumptions!$B$98)^1 -> 78000 | L28: =D28*$H$28*(1+Assumptions!$B$98)^2 -> 162240 | M28: =E28*$H$28*(1+Assumptions!$B$98)^3 -> 168729.6 | N28: =F28*$H$28*(1+Assumptions!$B$98)^4 -> 263218.18
A29: Content/Community Manager | B29: 0 | C29: 1 | D29: 1 | E29: 2 | F29: 3 | H29: 65000 | J29: =B29*$H$29 -> 0 | K29: =C29*$H$29*(1+Assumptions!$B$98)^1 -> 67600 | L29: =D29*$H$29*(1+Assumptions!$B$98)^2 -> 70304 | M29: =E29*$H$29*(1+Assumptions!$B$98)^3 -> 146232.32 | N29: =F29*$H$29*(1+Assumptions!$B$98)^4 -> 228122.42
A30: Total SALES & MARKETING | B30: =SUM(B26:B29) -> 0.5 | C30: =SUM(C26:C29) -> 3 | D30: =SUM(D26:D29) -> 6 | E30: =SUM(E26:E29) -> 9 | F30: =SUM(F26:F29) -> 15 | J30: =SUM(J26:J29) -> 37500 | K30: =SUM(K26:K29) -> 234000 | L30: =SUM(L26:L29) -> 578656 | M30: =SUM(M26:M29) -> 866145.28 | N30: =SUM(N26:N29) -> 1462323.2
A32: 5. CUSTOMER SUCCESS
A33: Customer Success Lead | B33: 0 | C33: 1 | D33: 1 | E33: 1 | F33: 1 | H33: 90000 | J33: =B33*$H$33 -> 0 | K33: =C33*$H$33*(1+Assumptions!$B$98)^1 -> 93600 | L33: =D33*$H$33*(1+Assumptions!$B$98)^2 -> 97344 | M33: =E33*$H$33*(1+Assumptions!$B$98)^3 -> 101237.76 | N33: =F33*$H$33*(1+Assumptions!$B$98)^4 -> 105287.27
A34: Brand Onboarding Specialist | B34: 0 | C34: 0 | D34: 1 | E34: 3 | F34: 6 | H34: 65000 | J34: =B34*$H$34 -> 0 | K34: =C34*$H$34*(1+Assumptions!$B$98)^1 -> 0 | L34: =D34*$H$34*(1+Assumptions!$B$98)^2 -> 70304 | M34: =E34*$H$34*(1+Assumptions!$B$98)^3 -> 219348.48 | N34: =F34*$H$34*(1+Assumptions!$B$98)^4 -> 456244.84
A35: Creator Community Manager | B35: 1 | C35: 1 | D35: 1 | E35: 2 | F35: 4 | H35: 60000 | J35: =B35*$H$35 -> 60000 | K35: =C35*$H$35*(1+Assumptions!$B$98)^1 -> 62400 | L35: =D35*$H$35*(1+Assumptions!$B$98)^2 -> 64896 | M35: =E35*$H$35*(1+Assumptions!$B$98)^3 -> 134983.68 | N35: =F35*$H$35*(1+Assumptions!$B$98)^4 -> 280766.05
A36: Total CUSTOMER SUCCESS | B36: =SUM(B33:B35) -> 1 | C36: =SUM(C33:C35) -> 2 | D36: =SUM(D33:D35) -> 3 | E36: =SUM(E33:E35) -> 6 | F36: =SUM(F33:F35) -> 11 | J36: =SUM(J33:J35) -> 60000 | K36: =SUM(K33:K35) -> 156000 | L36: =SUM(L33:L35) -> 232544 | M36: =SUM(M33:M35) -> 455569.92 | N36: =SUM(N33:N35) -> 842298.16
A38: 6. GENERAL & ADMINISTRATIVE
A39: Financial Analyst | B39: 0 | C39: 0 | D39: 1 | E39: 1 | F39: 1 | H39: 85000 | J39: =B39*$H$39 -> 0 | K39: =C39*$H$39*(1+Assumptions!$B$98)^1 -> 0 | L39: =D39*$H$39*(1+Assumptions!$B$98)^2 -> 91936 | M39: =E39*$H$39*(1+Assumptions!$B$98)^3 -> 95613.44 | N39: =F39*$H$39*(1+Assumptions!$B$98)^4 -> 99437.978
A40: HR/Ops Manager | B40: 0 | C40: 0 | D40: 0 | E40: 1 | F40: 1 | H40: 80000 | J40: =B40*$H$40 -> 0 | K40: =C40*$H$40*(1+Assumptions!$B$98)^1 -> 0 | L40: =D40*$H$40*(1+Assumptions!$B$98)^2 -> 0 | M40: =E40*$H$40*(1+Assumptions!$B$98)^3 -> 89989.12 | N40: =F40*$H$40*(1+Assumptions!$B$98)^4 -> 93588.685
A41: Legal Counsel (part-time/contract) | B41: 0 | C41: 0.5 | D41: 1 | E41: 1 | F41: 1 | H41: 120000 | J41: =B41*$H$41 -> 0 | K41: =C41*$H$41*(1+Assumptions!$B$98)^1 -> 62400 | L41: =D41*$H$41*(1+Assumptions!$B$98)^2 -> 129792 | M41: =E41*$H$41*(1+Assumptions!$B$98)^3 -> 134983.68 | N41: =F41*$H$41*(1+Assumptions!$B$98)^4 -> 140383.03
A42: Office/Admin | B42: 0 | C42: 0 | D42: 0 | E42: 1 | F42: 1 | H42: 55000 | J42: =B42*$H$42 -> 0 | K42: =C42*$H$42*(1+Assumptions!$B$98)^1 -> 0 | L42: =D42*$H$42*(1+Assumptions!$B$98)^2 -> 0 | M42: =E42*$H$42*(1+Assumptions!$B$98)^3 -> 61867.52 | N42: =F42*$H$42*(1+Assumptions!$B$98)^4 -> 64342.221
A43: Total GENERAL & ADMINISTRATIVE | B43: =SUM(B39:B42) -> 0 | C43: =SUM(C39:C42) -> 0.5 | D43: =SUM(D39:D42) -> 2 | E43: =SUM(E39:E42) -> 4 | F43: =SUM(F39:F42) -> 4 | J43: =SUM(J39:J42) -> 0 | K43: =SUM(K39:K42) -> 62400 | L43: =SUM(L39:L42) -> 221728 | M43: =SUM(M39:M42) -> 382453.76 | N43: =SUM(N39:N42) -> 397751.91
A45: SUMMARY
A46: Total Headcount | B46: =B9+B18+B23+B30+B36+B43 -> 5.5 | C46: =C9+C18+C23+C30+C36+C43 -> 13.5 | D46: =D9+D18+D23+D30+D36+D43 -> 25 | E46: =E9+E18+E23+E30+E36+E43 -> 42 | F46: =F9+F18+F23+F30+F36+F43 -> 63
A47: Total Salary Cost | J47: =J9+J18+J23+J30+J36+J43 -> 527500 | K47: =K9+K18+K23+K30+K36+K43 -> 1450800 | L47: =L9+L18+L23+L30+L36+L43 -> 2898688 | M47: =M9+M18+M23+M30+M36+M43 -> 4910031.4 | N47: =N9+N18+N23+N30+N36+N43 -> 7533889.1
...

Sheet Rev Model Assumptions
A1: HypeStake - Revenue Model Assumptions
A3: TABLE 1: TRANSACTION FEE REVENUE DRIVERS
A4: Category | B4: Assumption | C4: Value | D4: Source/Justification
A5: Deal Size | B5: Pure Equity Avg Cash | C5: =Assumptions!B12 -> 0 | D5: No cash flows through platform
A6: Deal Size | B6: Revenue Share Avg Quarterly Payout | C6: =Assumptions!B13 -> 2500 | D6: Per-quarter cash payout processed
A7: Deal Size | B7: Cash Deal Avg Size | C7: =Assumptions!B14 -> 5000 | D7: One-time deal brokering
A8: Deal Size | B8: Hybrid Deal Avg Cash Component | C8: =Assumptions!B15 -> 3500 | D8: Cash portion of hybrid deals
A9: Deal Size | B9: Rev Share Tracking Fee Base | C9: =Assumptions!B16 -> 1200 | D9: Quarterly attributed sales base
A10: Take-Rate | B10: Pure Equity Take-Rate | C10: =Assumptions!C12 -> 0 | D10: No cash = no take
A11: Take-Rate | B11: Revenue Share Take-Rate | C11: =Assumptions!C13 -> 0.08 | D11: % of cash payouts processed
A12: Take-Rate | B12: Cash Deal Take-Rate | C12: =Assumptions!C14 -> 0.1 | D12: Flat fee deal brokering
A13: Take-Rate | B13: Hybrid Deal Take-Rate | C13: =Assumptions!C15 -> 0.09 | D13: Blended rate on cash portion
A14: Take-Rate | B14: Rev Share Tracking Take-Rate | C14: =Assumptions!C16 -> 0.05 | D14: Ongoing commission tracking
A15: Take-Rate | B15: Blended Avg Take-Rate | C15: =Assumptions!C18 -> 0.064 | D15: Marketplace benchmarks: Upwork 10-20%, Fiverr 20%, Carta 0.5-1% of AUM. HypeStake 8-10% competitive for high-value deal brokering.
A16: Payout Freq | B16: Rev Share Ongoing Payouts/Year | C16: =Assumptions!B71 -> 4 | D16: Quarterly payouts per active deal
A19: TABLE 2: BRAND SUBSCRIPTION REVENUE DRIVERS
A20: Category | B20: Assumption | C20: Value | D20: Source/Justification
A21: Pricing | B21: Starter Monthly Price | C21: =Assumptions!B23 -> 149 | D21: Grin $999+/mo, AspireIQ $500+/mo. HypeStake Starter at $149/mo targets SMB segment.
A22: Pricing | B22: Professional Monthly Price | C22: =Assumptions!B24 -> 399 | D22: Comparable to AspireIQ mid-tier pricing
A23: Pricing | B23: Enterprise Monthly Price | C23: =Assumptions!B25 -> 999 | D23: CreatorIQ enterprise custom ($2K+/mo). HypeStake Enterprise $999/mo is competitive.
A24: Waiver | B24: Year 1 Waiver Flag | C24: =Assumptions!F27 -> 0 | D24: 1 = $0 subscription revenue in Y1. Waiving Y1 drives adoption.
A25: Conversion | B25: Explorer→Paid Conversion Rate | C25: Y2 | D25: Y3 | E25: Y4 | F25: Y5
A26: Conversion | B26: Explorer→Paid Conversion % | C26: =Assumptions!C43 -> 0.12 | D26: =Assumptions!D43 -> 0.15 | E26: =Assumptions!E43 -> 0.18 | F26: =Assumptions!F43 -> 0.2
A28: Growth | B28: Deal Volume Growth Rate | C28: Y1 | D28: Y2 | E28: Y3 | F28: Y4 | G28: Y5
A29: Growth | B29: Annual Deal Volume Growth % | C29: Baseline | D29: 2 | E29: 3 | F29: 1.5 | G29: 1
A31: TABLE 3: PREMIUM ADD-ON REVENUE DRIVERS
A32: Category | B32: Assumption | C32: Value | D32: Source/Justification
A33: Add-On | B33: Compliance Module Price | C33: =Assumptions!B31 -> 99 | D33: Carta compliance $100-300/mo, Pulley $50-200/mo. HypeStake at $99/mo aligned.
A34: Add-On | B34: Analytics Pack Price | C34: =Assumptions!B32 -> 49 | D34: Creator Genome deep insights upsell
A35: Add-On | B35: Early Liquidity Module Price | C35: =Assumptions!B33 -> 199 | D35: Secondary market access for creator equity positions
A36: Attach | B36: Avg Add-On Attach Rate | C36: =Assumptions!C34 -> 0.15 | D36: 15% of paying brands purchase at least 1 add-on
A37: ARPU | B37: Blended Add-On ARPU/Paying Brand | C37: =(Assumptions!B31+Assumptions!B32+Assumptions!B33)/3*Assumptions!C34 -> 17.35 | D37: Avg monthly add-on rev per paying brand (attach rate × avg module price)
A39: TABLE 4: EXPANSION RATES (ARR→Expansion% Lookup)
A40: ARR Range | B40: Net Expansion %
A41: <$300K ARR | B41: =Assumptions!B75 -> 0.1
A42: $300K–$1M ARR | B42: =Assumptions!B76 -> 0.18
A43: $1M–$3M ARR | B43: =Assumptions!B77 -> 0.25
A44: $3M–$8M ARR | B44: =Assumptions!B78 -> 0.3
A45: $8M–$15M ARR | B45: =Assumptions!B79 -> 0.32
A46: $15M+ ARR | B46: =Assumptions!B80 -> 0.35
...

Sheet Cost of Revenue
A1: HypeStake - Cost of Revenue
B2: 2026 | C2: 2027 | D2: 2028 | E2: 2029 | F2: 2030
A3: SECTION 1: USER COUNTS
A4: Total Creators on Platform | B4: =Assumptions!B40 -> 500 | C4: =Assumptions!C40 -> 2000 | D4: =Assumptions!D40 -> 8000 | E4: =Assumptions!E40 -> 20000 | F4: =Assumptions!F40 -> 50000
A5: Active Creators (completed ≥1 deal) | B5: =Assumptions!B40*Assumptions!B41 -> 75 | C5: =Assumptions!C40*Assumptions!C41 -> 400 | D5: =Assumptions!D40*Assumptions!D41 -> 2000 | E5: =Assumptions!E40*Assumptions!E41 -> 6000 | F5: =Assumptions!F40*Assumptions!F41 -> 17500
A6: Total Brands (Starter+Pro+Enterprise) | B6: =Assumptions!B52+Assumptions!B53+Assumptions!B54 -> 115 | C6: =Assumptions!C52+Assumptions!C53+Assumptions!C54 -> 295 | D6: =Assumptions!D52+Assumptions!D53+Assumptions!D54 -> 740 | E6: =Assumptions!E52+Assumptions!E53+Assumptions!E54 -> 1480 | F6: =Assumptions!F52+Assumptions!F53+Assumptions!F54 -> 2960
A7: Total Platform Users | B7: =B4+B6 -> 615 | C7: =C4+C6 -> 2295 | D7: =D4+D6 -> 8740 | E7: =E4+E6 -> 21480 | F7: =F4+F6 -> 52960
A8: Total Deals (from Assumptions) | B8: =Assumptions!B69 -> 140 | C8: =Assumptions!C69 -> 630 | D8: =Assumptions!D69 -> 2500 | E8: =Assumptions!E69 -> 6300 | F8: =Assumptions!F69 -> 16000
A10: SECTION 3: AI/LLM INFERENCE COSTS
A11: A) Creator Genome Algorithm | B11: ='LLM Costs'!B12*B5*12*'LLM Costs'!B52 -> 72.9 | C11: ='LLM Costs'!B12*C5*12*'LLM Costs'!C52 -> 194.4 | D11: ='LLM Costs'!B12*D5*12*'LLM Costs'!D52 -> 486 | E11: ='LLM Costs'!B12*E5*12*'LLM Costs'!E52 -> 729 | F11: ='LLM Costs'!B12*F5*12*'LLM Costs'!F52 -> 1063.125 | G11: Active creators × monthly cost × 12 × reduction factor
A12: B) Dynamic Deal Architect | B12: ='LLM Costs'!C20*B8*'LLM Costs'!B52 -> 37.8 | C12: ='LLM Costs'!C20*C8*'LLM Costs'!C52 -> 85.05 | D12: ='LLM Costs'!C20*D8*'LLM Costs'!D52 -> 168.75 | E12: ='LLM Costs'!C20*E8*'LLM Costs'!E52 -> 212.625 | F12: ='LLM Costs'!C20*F8*'LLM Costs'!F52 -> 270 | G12: Deals × cost per deal × reduction factor
A13: C) Smart Vesting Protocol | B13: ='LLM Costs'!C27*B8*12*'LLM Costs'!B52 -> 15.12 | C13: ='LLM Costs'!C27*C8*12*'LLM Costs'!C52 -> 34.02 | D13: ='LLM Costs'!C27*D8*12*'LLM Costs'!D52 -> 67.5 | E13: ='LLM Costs'!C27*E8*12*'LLM Costs'!E52 -> 85.05 | F13: ='LLM Costs'!C27*F8*12*'LLM Costs'!F52 -> 108 | G13: Active deals × monthly cost × 12 × reduction
A14: D) AI Brand/Creator Tools | B14: =(B5*'LLM Costs'!B35+B6*'LLM Costs'!C36)*12*'LLM Costs'!B52 -> 76.86 | C14: =(C5*'LLM Costs'!B35+C6*'LLM Costs'!C36)*12*'LLM Costs'!C52 -> 124.74 | D14: =(D5*'LLM Costs'!B35+D6*'LLM Costs'!C36)*12*'LLM Costs'!D52 -> 219.24 | E14: =(E5*'LLM Costs'!B35+E6*'LLM Costs'!C36)*12*'LLM Costs'!E52 -> 282.24 | F14: =(F5*'LLM Costs'!B35+F6*'LLM Costs'!C36)*12*'LLM Costs'!F52 -> 368.865 | G14: (Creators×2 + Brands×4) × $0.10 equiv × 12 × reduction
A15: Total AI/LLM Costs | B15: =SUM(B11:B14) -> 202.68 | C15: =SUM(C11:C14) -> 438.21 | D15: =SUM(D11:D14) -> 941.49 | E15: =SUM(E11:E14) -> 1308.915 | F15: =SUM(F11:F14) -> 1809.99
A17: SECTION 4: INFRASTRUCTURE COSTS
A18: Cloud Hosting (AWS/Azure) | B18: =(B7*0.5+B8*0.02)*12 -> 3723.6 | C18: =(C7*0.5+C8*0.02)*12 -> 13921.2 | D18: =(D7*0.5+D8*0.02)*12 -> 53040 | E18: =(E7*0.5+E8*0.02)*12 -> 130392 | F18: =(F7*0.5+F8*0.02)*12 -> 321600 | G18: $0.50/user/mo + $0.02/deal
A19: Database Costs | B19: =B7*0.15*12 -> 1107 | C19: =C7*0.15*12 -> 4131 | D19: =D7*0.15*12 -> 15732 | E19: =E7*0.15*12 -> 38664 | F19: =F7*0.15*12 -> 95328 | G19: $0.15/user/mo
A20: CDN & Content Delivery | B20: =B7*0.05*12 -> 369 | C20: =C7*0.05*12 -> 1377 | D20: =D7*0.05*12 -> 5244 | E20: =E7*0.05*12 -> 12888 | F20: =F7*0.05*12 -> 31776 | G20: $0.05/user/mo
A21: Security & Compliance Infra | B21: =(500+B6*0.1)*12 -> 6138 | C21: =(500+C6*0.1)*12 -> 6354 | D21: =(500+D6*0.1)*12 -> 6888 | E21: =(500+E6*0.1)*12 -> 7776 | F21: =(500+F6*0.1)*12 -> 9552 | G21: $500/mo base + $0.10/brand/mo
A22: Volume Discount (committed-use) | B22: =-SUM(B18:B21)*Assumptions!B96 -> 0 | C22: =-SUM(C18:C21)*Assumptions!C96 -> 0 | D22: =-SUM(D18:D21)*Assumptions!D96 -> -8090.4 | E22: =-SUM(E18:E21)*Assumptions!E96 -> -28458 | F22: =-SUM(F18:F21)*Assumptions!F96 -> -91651.2 | G22: From Assumptions: committed-use pricing
A23: Total Infrastructure Costs | B23: =SUM(B18:B22) -> 11337.6 | C23: =SUM(C18:C22) -> 25783.2 | D23: =SUM(D18:D22) -> 72813.6 | E23: =SUM(E18:E22) -> 161262 | F23: =SUM(F18:F22) -> 366604.8
A25: SECTION 5: CUSTOMER SUPPORT COSTS
A26: Creator Support ($0.50/mo) | B26: =B5*0.5*12 -> 450 | C26: =C5*0.5*12 -> 2400 | D26: =D5*0.5*12 -> 12000 | E26: =E5*0.5*12 -> 36000 | F26: =F5*0.5*12 -> 105000 | G26: Mostly self-serve
A27: Brand Support (Starter $5, Pro $15, Ent $50/mo) | B27: =(Assumptions!B52*5+Assumptions!B53*15+Assumptions!B54*50)*12 -> 13200 | C27: =(Assumptions!C52*5+Assumptions!C53*15+Assumptions!C54*50)*12 -> 35400 | D27: =(Assumptions!D52*5+Assumptions!D53*15+Assumptions!D54*50)*12 -> 90000 | E27: =(Assumptions!E52*5+Assumptions!E53*15+Assumptions!E54*50)*12 -> 180000 | F27: =(Assumptions!F52*5+Assumptions!F53*15+Assumptions!F54*50)*12 -> 360000 | G27: Tiered support by brand level
A28: Total Support Costs | B28: =SUM(B26:B27) -> 13650 | C28: =SUM(C26:C27) -> 37800 | D28: =SUM(D26:D27) -> 102000 | E28: =SUM(E26:E27) -> 216000 | F28: =SUM(F26:F27) -> 465000
A30: SECTION 5B: PAYMENT PROCESSING COSTS
A31: Payment Processing (scaled rate) | B31: ='Income Statement'!B10*Assumptions!B95 -> 11375.337 | C31: ='Income Statement'!C10*Assumptions!C95 -> 33867.911 | D31: ='Income Statement'!D10*Assumptions!D95 -> 83909.7 | E31: ='Income Statement'!E10*Assumptions!E95 -> 160331.07 | F31: ='Income Statement'!F10*Assumptions!F95 -> 356907.14 | G31: Stripe/processor fee on all revenue collected
A32: Per-Transaction Fixed Fee ($0.30) | B32: =(B6*12+B8)*0.3 -> 456 | C32: =(C6*12+C8)*0.3 -> 1251 | D32: =(D6*12+D8)*0.3 -> 3414 | E32: =(E6*12+E8)*0.3 -> 7218 | F32: =(F6*12+F8)*0.3 -> 15456 | G32: Est. on subscription + deal transactions
A33: Total Payment Processing Costs | B33: =SUM(B31:B32) -> 11831.337 | C33: =SUM(C31:C32) -> 35118.911 | D33: =SUM(D31:D32) -> 87323.7 | E33: =SUM(E31:E32) -> 167549.07 | F33: =SUM(F31:F32) -> 372363.14
A35: SECTION 5C: COMPLIANCE, DATA & ESCROW COSTS
A36: Compliance Monitoring (AML/KYC/SEC) | B36: =Assumptions!$B$92*B8 -> 2100 | C36: =Assumptions!$B$92*C8 -> 9450 | D36: =Assumptions!$B$92*D8 -> 37500 | E36: =Assumptions!$B$92*E8 -> 94500 | F36: =Assumptions!$B$92*F8 -> 240000 | G36: $15/deal/yr from Assumptions
A37: Third-Party Data APIs (Creator Genome) | B37: =Assumptions!$B$93*B5 -> 225 | C37: =Assumptions!$B$93*C5 -> 1200 | D37: =Assumptions!$B$93*D5 -> 6000 | E37: =Assumptions!$B$93*E5 -> 18000 | F37: =Assumptions!$B$93*F5 -> 52500 | G37: $3/active creator/yr from Assumptions
A38: Escrow/Custodial Services | B38: =Assumptions!$B$94*B8 -> 2800 | C38: =Assumptions!$B$94*C8 -> 12600 | D38: =Assumptions!$B$94*D8 -> 50000 | E38: =Assumptions!$B$94*E8 -> 126000 | F38: =Assumptions!$B$94*F8 -> 320000 | G38: $20/deal from Assumptions
A39: Total Compliance/Data/Escrow Costs | B39: =SUM(B36:B38) -> 5125 | C39: =SUM(C36:C38) -> 23250 | D39: =SUM(D36:D38) -> 93500 | E39: =SUM(E36:E38) -> 238500 | F39: =SUM(F36:F38) -> 612500
A42: SECTION 6: TOTAL COST OF REVENUE
A43: Total AI/LLM Costs | B43: =B15 -> 202.68 | C43: =C15 -> 438.21 | D43: =D15 -> 941.49 | E43: =E15 -> 1308.915 | F43: =F15 -> 1809.99
A44: Total Infrastructure Costs | B44: =B23 -> 11337.6 | C44: =C23 -> 25783.2 | D44: =D23 -> 72813.6 | E44: =E23 -> 161262 | F44: =F23 -> 366604.8
A45: Total Support Costs | B45: =B28 -> 13650 | C45: =C28 -> 37800 | D45: =D28 -> 102000 | E45: =E28 -> 216000 | F45: =F28 -> 465000
A46: Total Payment Processing Costs | B46: =B33 -> 11831.337 | C46: =C33 -> 35118.911 | D46: =D33 -> 87323.7 | E46: =E33 -> 167549.07 | F46: =F33 -> 372363.14
A47: Total Compliance/Data/Escrow Costs | B47: =B39 -> 5125 | C47: =C39 -> 23250 | D47: =D39 -> 93500 | E47: =E39 -> 238500 | F47: =F39 -> 612500
...

Sheet API Costs
A1: HypeStake - AI/API Cost Details
A3: This sheet is a reference index. All AI/API costs are modeled in the following sheets:
A4: → 'LLM Costs': Detailed per-user AI pipeline costs (Genome, Deal Architect, Vesting, AI Tools)
A5: → 'Cost of Revenue': Infrastructure, support, payment processing, compliance, and total COGS
A6: → 'Assumptions': Central control panel for all cost rates (rows 88-97)
A8: Key cost assumptions: LLM costs reduce 50% annually (conservative vs 5-10x/yr observed). Payment processing scales from 2.9% to 2.2% at volume. Infrastructure volume discounts apply Y3+.

Sheet LLM Costs
A1: HypeStake - AI Pipeline Cost Model (Monthly Per User)
A3: TABLE 1: CREATOR GENOME ALGORITHM
A4: Component | B4: Per Creator | C4: Per Brand | D4: Formula/Notes
A5: Genome scans per month | B5: 1.5 | C5: 0 | D5: 1 initial + 0.5 re-scans/mo for existing
A6: Tokens per scan (input) | B6: 8000 | D6: Creator data + social metrics + audience demographics
A7: Tokens per scan (output) | B7: 2000 | D7: Structured JSON genome report
A8: Cost per 1K tokens (input) | B8: 0.003 | D8: Claude/GPT-4 tier inference
A9: Cost per 1K tokens (output) | B9: 0.015 | D9: Claude/GPT-4 tier inference
A10: Total tokens in (thousands) | B10: =B5*B6/1000 -> 12 | D10: scans × tokens_in / 1000
A11: Total tokens out (thousands) | B11: =B5*B7/1000 -> 3 | D11: scans × tokens_out / 1000
A12: Genome Stage Cost/Creator/Month | B12: =B10*B8+B11*B9 -> 0.081 | D12: tokens_in_k × cost_in + tokens_out_k × cost_out
A14: TABLE 2: DYNAMIC DEAL ARCHITECT
A15: Component | B15: Value | C15: Per-Deal Cost | D15: Formula/Notes
A16: Deal structuring requests/deal | B16: 3 | D16: Initial offer + 2 counter-offer iterations
A17: Context tokens per request | B17: 15000 | D17: Creator genome + brand profile + deal terms + market data
A18: Response tokens per request | B18: 3000 | D18: Structured deal proposal JSON
A19: Cost per 1K tokens (in/out) | B19: $0.003 / $0.015 | D19: Claude/GPT-4 tier
A20: Deal Architect Cost/Deal | C20: =B16*(B17/1000*0.003+B18/1000*0.015) -> 0.27 | D20: requests × (in_tokens×cost_in + out_tokens×cost_out)
A22: TABLE 3: SMART VESTING PROTOCOL
A23: Component | B23: Value | C23: Monthly Cost/Deal | D23: Formula/Notes
A24: Vesting checks/active deal/month | B24: 2 | D24: Monthly compliance/vesting verification
A25: Tokens per check (in/out) | B25: 2,000 / 500 | D25: Lighter model — Haiku/Flash tier
A26: Cost per 1K tokens (in/out) | B26: $0.001 / $0.005 | D26: Claude Haiku / GPT-4o-mini tier
A27: Vesting Cost/Active Deal/Month | C27: =B24*(2000/1000*$B$48+500/1000*$C$48) -> 0.009 | D27: checks × (in_tokens×cost_in + out_tokens×cost_out)
A29: TABLE 4: AI TOOLS (Profile Builder, Deal Analyzer, Content Strategy, Brand Tools)
A30: Component | B30: Per Creator | C30: Per Brand | D30: Formula/Notes
A31: Avg uses per month | B31: 2 | C31: 4
A32: Tokens per use (input) | B32: 3000 | C32: 3000
A33: Tokens per use (output) | B33: 1500 | C33: 1500
A34: Cost per 1K tokens (in/out) | B34: $0.001 / $0.005 | C34: $0.001 / $0.005 | D34: Mid-tier model (blended)
A35: AI Tools Cost/Creator/Month | B35: =B31*(B32/1000*$B$48+B33/1000*$C$48) -> 0.021 | D35: uses × (in_k×cost_in + out_k×cost_out)
A36: AI Tools Cost/Brand/Month | C36: =C31*(C32/1000*$B$48+C33/1000*$C$48) -> 0.042 | D36: uses × (in_k×cost_in + out_k×cost_out)
A38: SUMMARY: TOTAL MONTHLY LLM COSTS PER USER TYPE
A39: User Type | B39: Monthly LLM Cost | C39: Components
A40: Per Creator | B40: =B12+B35 -> 0.102 | C40: Genome + AI Tools
A41: Per Brand | B41: =C36 -> 0.042 | C41: AI Tools only (brands don't get genome scans)
A42: Per Deal (one-time) | B42: =C20 -> 0.27 | C42: Deal Architect cost
A43: Per Active Deal (monthly) | B43: =C27 -> 0.009 | C43: Vesting Protocol cost
A45: LLM PRICING REFERENCE
A46: Model Tier | B46: Input/1K | C46: Output/1K | D46: Used For
...

Sheet Yearly Summary
A1: HypeStake - Yearly Summary
B2: Y1 (2026) | C2: Y2 (2027) | D2: Y3 (2028) | E2: Y4 (2029) | F2: Y5 (2030)
A3: MARKETPLACE METRICS
A4: Total Creators on Platform | B4: =Assumptions!B40 -> 500 | C4: =Assumptions!C40 -> 2000 | D4: =Assumptions!D40 -> 8000 | E4: =Assumptions!E40 -> 20000 | F4: =Assumptions!F40 -> 50000
A5: Active Creators (deal-making) | B5: ='Cost of Revenue'!B5 -> 75 | C5: ='Cost of Revenue'!C5 -> 400 | D5: ='Cost of Revenue'!D5 -> 2000 | E5: ='Cost of Revenue'!E5 -> 6000 | F5: ='Cost of Revenue'!F5 -> 17500
A6: Brands - Starter | B6: =Assumptions!B52 -> 80 | C6: =Assumptions!C52 -> 200 | D6: =Assumptions!D52 -> 500 | E6: =Assumptions!E52 -> 1000 | F6: =Assumptions!F52 -> 2000
A7: Brands - Professional | B7: =Assumptions!B53 -> 30 | C7: =Assumptions!C53 -> 80 | D7: =Assumptions!D53 -> 200 | E7: =Assumptions!E53 -> 400 | F7: =Assumptions!F53 -> 800
